
Traceback (most recent call last):
  File "C:\Users\Mittal\anaconda3\envs\tf2.5\lib\site-packages\keras\saving\hdf5_format.py", line 126, in save_model_to_hdf5
    save_optimizer_weights_to_hdf5_group(f, model.optimizer)
  File "C:\Users\Mittal\anaconda3\envs\tf2.5\lib\site-packages\keras\saving\hdf5_format.py", line 600, in save_optimizer_weights_to_hdf5_group
    param_dset[:] = val
  File "h5py\_objects.pyx", line 54, in h5py._objects.with_phil.wrapper
  File "h5py\_objects.pyx", line 55, in h5py._objects.with_phil.wrapper
  File "C:\Users\Mittal\anaconda3\envs\tf2.5\lib\site-packages\h5py\_hl\dataset.py", line 945, in __setitem__
    self.id.write(mspace, fspace, val, mtype, dxpl=self._dxpl)
  File "h5py\_objects.pyx", line 54, in h5py._objects.with_phil.wrapper
  File "h5py\_objects.pyx", line 55, in h5py._objects.with_phil.wrapper
  File "h5py\h5d.pyx", line 232, in h5py.h5d.DatasetID.write
  File "h5py\_proxy.pyx", line 114, in h5py._proxy.dset_rw
OSError: Can't write data (file write failed: time = Fri Jun 21 13:06:46 2024
, filename = 'C:/Users/Mittal/Desktop/kunet\model2_0.h5', file descriptor = 3, errno = 28, error message = 'No space left on device', buf = 0000022937C46040, total write size = 37748736, bytes this sub-write = 37748736, bytes actually written = 18446744073709551615, offset = 286747256)

During handling of the above exception, another exception occurred:

Traceback (most recent call last):
  File "multikunet.py", line 426, in <module>
    history = model.fit(X_train, y_train_cat,
  File "C:\Users\Mittal\anaconda3\envs\tf2.5\lib\site-packages\keras\engine\training.py", line 1204, in fit
    callbacks.on_epoch_end(epoch, epoch_logs)
  File "C:\Users\Mittal\anaconda3\envs\tf2.5\lib\site-packages\keras\callbacks.py", line 410, in on_epoch_end
    callback.on_epoch_end(epoch, logs)
  File "C:\Users\Mittal\anaconda3\envs\tf2.5\lib\site-packages\keras\callbacks.py", line 1376, in on_epoch_end
    self._save_model(epoch=epoch, logs=logs)
  File "C:\Users\Mittal\anaconda3\envs\tf2.5\lib\site-packages\keras\callbacks.py", line 1428, in _save_model
    self.model.save(filepath, overwrite=True, options=self._options)
  File "C:\Users\Mittal\anaconda3\envs\tf2.5\lib\site-packages\keras\engine\training.py", line 2086, in save
    save.save_model(self, filepath, overwrite, include_optimizer, save_format,
  File "C:\Users\Mittal\anaconda3\envs\tf2.5\lib\site-packages\keras\saving\save.py", line 146, in save_model
    hdf5_format.save_model_to_hdf5(
  File "C:\Users\Mittal\anaconda3\envs\tf2.5\lib\site-packages\keras\saving\hdf5_format.py", line 131, in save_model_to_hdf5
    f.close()
  File "C:\Users\Mittal\anaconda3\envs\tf2.5\lib\site-packages\h5py\_hl\files.py", line 457, in close
    h5i.dec_ref(id_)
  File "h5py\_objects.pyx", line 54, in h5py._objects.with_phil.wrapper
  File "h5py\_objects.pyx", line 55, in h5py._objects.with_phil.wrapper
  File "h5py\h5i.pyx", line 153, in h5py.h5i.dec_ref
RuntimeError: Can't decrement id ref count (unable to extend file properly)
